Workbook

Sheet ExecutiveKPIs
A1: Vendor Risk Management & Supplier Performance Scorecard
A2: Executive KPI Summary -- Supply Chain / Procurement Risk Analytics
A4: Total Vendors | B4: =COUNTA(VendorMetrics!A2:A61) -> 60
A5: Total Procurement Spend | B5: =SUM(VendorMetrics!U2:U61) -> 4.0999366e+08
A6: Spend at High Risk (Total Spend with High-tier vendors) | B6: =SUMIFS(VendorMetrics!U2:U61,VendorMetrics!S2:S61,"High") -> 12830937
A7: % of Total Spend at High Risk | B7: =B6/B5 -> 0.031295452
A8: High-Risk Vendor Count | B8: =COUNTIF(VendorMetrics!S2:S61,"High") -> 1
A9: Strategic Vendors (high spend + high risk -- manage closely) | B9: =COUNTIF(VendorMetrics!X2:X61,"Strategic") -> 14
A10: Bottleneck Vendors (low spend but high risk -- secure alternatives) | B10: =COUNTIF(VendorMetrics!X2:X61,"Bottleneck") -> 16
A11: Leverage Vendors (high spend, low risk -- negotiate on price) | B11: =COUNTIF(VendorMetrics!X2:X61,"Leverage") -> 16
A12: Non-Critical Vendors (low spend, low risk -- simplify/automate) | B12: =COUNTIF(VendorMetrics!X2:X61,"Non-Critical") -> 14
A15: METHODOLOGY NOTE: Vendor segmentation uses a Kraljic Matrix approach -- Supply Risk axis = normalized RiskScore (median split), Business Impact axis = Total Spend (median split). See VendorMetrics sheet for full per-vendor detail.

Sheet README
A1: Enterprise Supply Chain Operational Risk & Vendor Performance Diagnostics
A2: Synthetic dataset — 60 vendors, 3,000 purchase orders, 2023–2024. Built for portfolio/learning use.
A4: Vendors
A5: One row per vendor. Master list of who supplies what.
A6: Columns: VendorID (key), VendorName, Category, Country, OnboardedDate, ContractType
A8: PurchaseOrders
A9: One row per order placed with a vendor. This is the core fact table.
A10: Columns: PO_ID (key), VendorID (link to Vendors), OrderDate, PromisedDeliveryDate, ActualDeliveryDate, OrderedQty, DeliveredQty, ContractedUnitPrice, InvoicedUnitPrice
A12: QualityInspections
A13: One row per inspection carried out on a delivered order.
A14: Columns: InspectionID (key), PO_ID (link to PurchaseOrders), InspectedQty, DefectiveQty, InspectionDate, DefectReason
A16: ShipmentTracking
... A18: Columns: PO_ID (link to PurchaseOrders), ShippedDate, CarrierName, Origin, Destination, DelayReason

Sheet Vendors
A1: VendorID | B1: VendorName | C1: Category | D1: Country | E1: OnboardedDate | F1: ContractType
A2: V001 | B2: Everest Supplies | C2: Packaging | D2: USA | E2: 43151 | F2: Long-term
A3: V002 | B3: Global Enterprises | C3: Packaging | D3: India | E3: 44531 | F3: Spot
A4: V003 | B4: Vertex Logistics | C4: Packaging | D4: India | E4: 43269 | F4: Long-term
A5: V004 | B5: Everest Manufacturing | C5: Electronics | D5: China | E5: 44578 | F5: Spot
A6: V005 | B6: Kiran Industries | C6: Raw Materials | D6: India | E6: 44752 | F6: Long-term
A7: V006 | B7: Apex Systems | C7: Electronics | D7: India | E7: 43363 | F7: Long-term
A8: V007 | B8: Kingfisher Supplies | C8: Raw Materials | D8: Germany | E8: 43968 | F8: Long-term
A9: V008 | B9: Jyoti Supplies | C9: Electronics | D9: India | E9: 43348 | F9: Annual
A10: V009 | B10: Zenith Traders | C10: MRO/Spares | D10: Germany | E10: 44235 | F10: Long-term
A11: V010 | B11: Precision Enterprises | C11: Raw Materials | D11: India | E11: 44956 | F11: Long-term
A12: V011 | B12: Zenith Pvt Ltd | C12: Raw Materials | D12: India | E12: 43262 | F12: Spot
A13: V012 | B13: Jupiter Systems | C13: Electronics | D13: Vietnam | E13: 43896 | F13: Long-term
... A61: V060 | B61: Delta Supplies | C61: Electronics | D61: Vietnam | E61: 44162 | F61: Long-term

Sheet PurchaseOrders
A1: PO_ID | B1: VendorID | C1: OrderDate | D1: PromisedDeliveryDate | E1: ActualDeliveryDate | F1: OrderedQty | G1: DeliveredQty | H1: ContractedUnitPrice | I1: InvoicedUnitPrice | J1: DelayDays | K1: OnTimeFlag | L1: FillRatePct | M1: PriceVariancePct | N1: LineTotal
A2: PO10001 | B2: V013 | C2: 45501 | D2: 45520 | E2: 45521 | F2: 118 | G2: 110 | H2: 1232.83 | I2: 1221.72 | J2: =E2-D2 -> 1 | K2: =IF(J2<=0,1,0) -> 0 | L2: =IFERROR(G2/F2,0) -> 0.93220339 | M2: =IFERROR((I2-H2)/H2,0) -> -0.0090117859 | N2: =G2*I2 -> 134389.2
A3: PO10002 | B3: V037 | C3: 45620 | D3: 45633 | E3: 45639 | F3: 115 | G3: 107 | H3: 396.01 | I3: 389.03 | J3: =E3-D3 -> 6 | K3: =IF(J3<=0,1,0) -> 0 | L3: =IFERROR(G3/F3,0) -> 0.93043478 | M3: =IFERROR((I3-H3)/H3,0) -> -0.017625818 | N3: =G3*I3 -> 41626.21
A4: PO10003 | B4: V040 | C4: 45052 | D4: 45064 | E4: 45065 | F4: 220 | G4: 210 | H4: 214.07 | I4: 220.9 | J4: =E4-D4 -> 1 | K4: =IF(J4<=0,1,0) -> 0 | L4: =IFERROR(G4/F4,0) -> 0.95454545 | M4: =IFERROR((I4-H4)/H4,0) -> 0.031905451 | N4: =G4*I4 -> 46389
A5: PO10004 | B5: V020 | C5: 45233 | D5: 45242 | E5: 45241 | F5: 1364 | G5: 1364 | H5: 101.36 | I5: 104.32 | J5: =E5-D5 -> -1 | K5: =IF(J5<=0,1,0) -> 1 | L5: =IFERROR(G5/F5,0) -> 1 | M5: =IFERROR((I5-H5)/H5,0) -> 0.029202841 | N5: =G5*I5 -> 142292.48
A6: PO10005 | B6: V044 | C6: 45410 | D6: 45420 | E6: 45415 | F6: 235 | G6: 223 | H6: 88.52 | I6: 89.41 | J6: =E6-D6 -> -5 | K6: =IF(J6<=0,1,0) -> 1 | L6: =IFERROR(G6/F6,0) -> 0.94893617 | M6: =IFERROR((I6-H6)/H6,0) -> 0.010054225 | N6: =G6*I6 -> 19938.43
A7: PO10006 | B7: V053 | C7: 45127 | D7: 45134 | E7: 45138 | F7: 3 | G7: 3 | H7: 1458.52 | I7: 1471.05 | J7: =E7-D7 -> 4 | K7: =IF(J7<=0,1,0) -> 0 | L7: =IFERROR(G7/F7,0) -> 1 | M7: =IFERROR((I7-H7)/H7,0) -> 0.0085909004 | N7: =G7*I7 -> 4413.15
A8: PO10007 | B8: V035 | C8: 45372 | D8: 45383 | E8: 45384 | F8: 659 | G8: 640 | H8: 170.42 | I8: 174.05 | J8: =E8-D8 -> 1 | K8: =IF(J8<=0,1,0) -> 0 | L8: =IFERROR(G8/F8,0) -> 0.97116844 | M8: =IFERROR((I8-H8)/H8,0) -> 0.021300317 | N8: =G8*I8 -> 111392
A9: PO10008 | B9: V053 | C9: 45629 | D9: 45635 | E9: 45635 | F9: 4 | G9: 4 | H9: 1458.52 | I9: 1472.05 | J9: =E9-D9 -> 0 | K9: =IF(J9<=0,1,0) -> 1 | L9: =IFERROR(G9/F9,0) -> 1 | M9: =IFERROR((I9-H9)/H9,0) -> 0.0092765269 | N9: =G9*I9 -> 5888.2
A10: PO10009 | B10: V049 | C10: 45170 | D10: 45190 | E10: 45191 | F10: 159 | G10: 155 | H10: 1252.36 | I10: 1219.89 | J10: =E10-D10 -> 1 | K10: =IF(J10<=0,1,0) -> 0 | L10: =IFERROR(G10/F10,0) -> 0.97484277 | M10: =IFERROR((I10-H10)/H10,0) -> -0.02592705 | N10: =G10*I10 -> 189082.95
A11: PO10010 | B11: V029 | C11: 45384 | D11: 45402 | E11: 45406 | F11: 322 | G11: 307 | H11: 442.74 | I11: 447.03 | J11: =E11-D11 -> 4 | K11: =IF(J11<=0,1,0) -> 0 | L11: =IFERROR(G11/F11,0) -> 0.95341615 | M11: =IFERROR((I11-H11)/H11,0) -> 0.0096896598 | N11: =G11*I11 -> 137238.21
A12: PO10011 | B12: V018 | C12: 45555 | D12: 45574 | E12: 45577 | F12: 125 | G12: 123 | H12: 821.48 | I12: 876.53 | J12: =E12-D12 -> 3 | K12: =IF(J12<=0,1,0) -> 0 | L12: =IFERROR(G12/F12,0) -> 0.984 | M12: =IFERROR((I12-H12)/H12,0) -> 0.067013196 | N12: =G12*I12 -> 107813.19
A13: PO10012 | B13: V024 | C13: 45255 | D13: 45275 | E13: 45273 | F13: 475 | G13: 451 | H13: 496.29 | I13: 501.76 | J13: =E13-D13 -> -2 | K13: =IF(J13<=0,1,0) -> 1 | L13: =IFERROR(G13/F13,0) -> 0.94947368 | M13: =IFERROR((I13-H13)/H13,0) -> 0.011021782 | N13: =G13*I13 -> 226293.76
... A3001: PO13000 | B3001: V009 | C3001: 45142 | D3001: 45153 | E3001: 45154 | F3001: 287 | G3001: 275 | H3001: 135.68 | I3001: 137.68 | J3001: =E3001-D3001 -> 1 | K3001: =IF(J3001<=0,1,0) -> 0 | L3001: =IFERROR(G3001/F3001,0) -> 0.95818815 | M3001: =IFERROR((I3001-H3001)/H3001,0) -> 0.014740566 | N3001: =G3001*I3001 -> 37862

Sheet QualityInspections
A1: InspectionID | B1: PO_ID | C1: InspectedQty | D1: DefectiveQty | E1: InspectionDate | F1: DefectReason | G1: VendorID
A2: Q50001 | B2: PO10001 | C2: 110 | D2: 5 | E2: 45522 | F2: Material defect | G2: =INDEX(PurchaseOrders!$B$2:$B$3001,MATCH(B2,PurchaseOrders!$A$2:$A$3001,0)) -> V013
A3: Q50002 | B3: PO10002 | C3: 107 | D3: 5 | E3: 45643 | F3: Surface finish issue | G3: =INDEX(PurchaseOrders!$B$2:$B$3001,MATCH(B3,PurchaseOrders!$A$2:$A$3001,0)) -> V037
A4: Q50003 | B4: PO10003 | C4: 210 | D4: 2 | E4: 45068 | F4: Missing components | G4: =INDEX(PurchaseOrders!$B$2:$B$3001,MATCH(B4,PurchaseOrders!$A$2:$A$3001,0)) -> V040
A5: Q50004 | B5: PO10004 | C5: 1364 | D5: 33 | E5: 45242 | F5: Wrong specification | G5: =INDEX(PurchaseOrders!$B$2:$B$3001,MATCH(B5,PurchaseOrders!$A$2:$A$3001,0)) -> V020
A6: Q50005 | B6: PO10005 | C6: 223 | D6: 22 | E6: 45416 | F6: Dimension mismatch | G6: =INDEX(PurchaseOrders!$B$2:$B$3001,MATCH(B6,PurchaseOrders!$A$2:$A$3001,0)) -> V044
A7: Q50006 | B7: PO10006 | C7: 3 | D7: 0 | E7: 45141 | G7: =INDEX(PurchaseOrders!$B$2:$B$3001,MATCH(B7,PurchaseOrders!$A$2:$A$3001,0)) -> V053
A8: Q50007 | B8: PO10007 | C8: 640 | D8: 4 | E8: 45385 | F8: Surface finish issue | G8: =INDEX(PurchaseOrders!$B$2:$B$3001,MATCH(B8,PurchaseOrders!$A$2:$A$3001,0)) -> V035
A9: Q50008 | B9: PO10008 | C9: 4 | D9: 0 | E9: 45637 | G9: =INDEX(PurchaseOrders!$B$2:$B$3001,MATCH(B9,PurchaseOrders!$A$2:$A$3001,0)) -> V053
A10: Q50009 | B10: PO10009 | C10: 155 | D10: 17 | E10: 45195 | F10: Dimension mismatch | G10: =INDEX(PurchaseOrders!$B$2:$B$3001,MATCH(B10,PurchaseOrders!$A$2:$A$3001,0)) -> V049
A11: Q50010 | B11: PO10010 | C11: 307 | D11: 13 | E11: 45409 | F11: Surface finish issue | G11: =INDEX(PurchaseOrders!$B$2:$B$3001,MATCH(B11,PurchaseOrders!$A$2:$A$3001,0)) -> V029
A12: Q50011 | B12: PO10011 | C12: 123 | D12: 4 | E12: 45581 | F12: Dimension mismatch | G12: =INDEX(PurchaseOrders!$B$2:$B$3001,MATCH(B12,PurchaseOrders!$A$2:$A$3001,0)) -> V018
A13: Q50012 | B13: PO10012 | C13: 451 | D13: 14 | E13: 45277 | F13: Missing components | G13: =INDEX(PurchaseOrders!$B$2:$B$3001,MATCH(B13,PurchaseOrders!$A$2:$A$3001,0)) -> V024
A14: Q50013 | B14: PO10013 | C14: 152 | D14: 13 | E14: 45370 | F14: Wrong specification | G14: =INDEX(PurchaseOrders!$B$2:$B$3001,MATCH(B14,PurchaseOrders!$A$2:$A$3001,0)) -> V009
A15: Q50014 | B15: PO10014 | C15: 1608 | D15: 112 | E15: 45124 | F15: Packaging damage | G15: =INDEX(PurchaseOrders!$B$2:$B$3001,MATCH(B15,PurchaseOrders!$A$2:$A$3001,0)) -> V034
A16: Q50015 | B16: PO10015 | C16: 229 | D16: 19 | E16: 45289 | F16: Material defect | G16: =INDEX(PurchaseOrders!$B$2:$B$3001,MATCH(B16,PurchaseOrders!$A$2:$A$3001,0)) -> V018
A17: Q50016 | B17: PO10016 | C17: 501 | D17: 2 | E17: 45114 | F17: Wrong specification | G17: =INDEX(PurchaseOrders!$B$2:$B$3001,MATCH(B17,PurchaseOrders!$A$2:$A$3001,0)) -> V020
A18: Q50017 | B18: PO10017 | C18: 737 | D18: 30 | E18: 45000 | F18: Dimension mismatch | G18: =INDEX(PurchaseOrders!$B$2:$B$3001,MATCH(B18,PurchaseOrders!$A$2:$A$3001,0)) -> V017
A19: Q50018 | B19: PO10018 | C19: 174 | D19: 16 | E19: 44989 | F19: Packaging damage | G19: =INDEX(PurchaseOrders!$B$2:$B$3001,MATCH(B19,PurchaseOrders!$A$2:$A$3001,0)) -> V009
A20: Q50019 | B20: PO10019 | C20: 220 | D20: 5 | E20: 45093 | F20: Dimension mismatch | G20: =INDEX(PurchaseOrders!$B$2:$B$3001,MATCH(B20,PurchaseOrders!$A$2:$A$3001,0)) -> V046
A21: Q50020 | B21: PO10020 | C21: 490 | D21: 18 | E21: 45071 | F21: Packaging damage | G21: =INDEX(PurchaseOrders!$B$2:$B$3001,MATCH(B21,PurchaseOrders!$A$2:$A$3001,0)) -> V021
A22: Q50021 | B22: PO10021 | C22: 9 | D22: 0 | E22: 45630 | G22: =INDEX(PurchaseOrders!$B$2:$B$3001,MATCH(B22,PurchaseOrders!$A$2:$A$3001,0)) -> V053
A23: Q50022 | B23: PO10022 | C23: 1618 | D23: 24 | E23: 45349 | F23: Packaging damage | G23: =INDEX(PurchaseOrders!$B$2:$B$3001,MATCH(B23,PurchaseOrders!$A$2:$A$3001,0)) -> V045
A24: Q50023 | B24: PO10023 | C24: 63 | D24: 0 | E24: 45019 | G24: =INDEX(PurchaseOrders!$B$2:$B$3001,MATCH(B24,PurchaseOrders!$A$2:$A$3001,0)) -> V046
A25: Q50024 | B25: PO10024 | C25: 191 | D25: 15 | E25: 44985 | F25: Material defect | G25: =INDEX(PurchaseOrders!$B$2:$B$3001,MATCH(B25,PurchaseOrders!$A$2:$A$3001,0)) -> V051
A26: Q50025 | B26: PO10025 | C26: 278 | D26: 6 | E26: 45628 | F26: Dimension mismatch | G26: =INDEX(PurchaseOrders!$B$2:$B$3001,MATCH(B26,PurchaseOrders!$A$2:$A$3001,0)) -> V051
A27: Q50026 | B27: PO10026 | C27: 3431 | D27: 573 | E27: 45315 | F27: Missing components | G27: =INDEX(PurchaseOrders!$B$2:$B$3001,MATCH(B27,PurchaseOrders!$A$2:$A$3001,0)) -> V026
A28: Q50027 | B28: PO10027 | C28: 29 | D28: 1 | E28: 45248 | F28: Missing components | G28: =INDEX(PurchaseOrders!$B$2:$B$3001,MATCH(B28,PurchaseOrders!$A$2:$A$3001,0)) -> V037
A29: Q50028 | B29: PO10028 | C29: 4101 | D29: 169 | E29: 45490 | F29: Missing components | G29: =INDEX(PurchaseOrders!$B$2:$B$3001,MATCH(B29,PurchaseOrders!$A$2:$A$3001,0)) -> V058
A30: Q50029 | B30: PO10029 | C30: 193 | D30: 23 | E30: 45619 | F30: Packaging damage | G30: =INDEX(PurchaseOrders!$B$2:$B$3001,MATCH(B30,PurchaseOrders!$A$2:$A$3001,0)) -> V049
A31: Q50030 | B31: PO10030 | C31: 61 | D31: 4 | E31: 45666 | F31: Missing components | G31: =INDEX(PurchaseOrders!$B$2:$B$3001,MATCH(B31,PurchaseOrders!$A$2:$A$3001,0)) -> V012
A32: Q50031 | B32: PO10031 | C32: 749 | D32: 102 | E32: 45227 | F32: Dimension mismatch | G32: =INDEX(PurchaseOrders!$B$2:$B$3001,MATCH(B32,PurchaseOrders!$A$2:$A$3001,0)) -> V044
A33: Q50032 | B33: PO10032 | C33: 9 | D33: 0 | E33: 45323 | G33: =INDEX(PurchaseOrders!$B$2:$B$3001,MATCH(B33,PurchaseOrders!$A$2:$A$3001,0)) -> V023
A34: Q50033 | B34: PO10033 | C34: 4587 | D34: 400 | E34: 45547 | F34: Missing components | G34: =INDEX(PurchaseOrders!$B$2:$B$3001,MATCH(B34,PurchaseOrders!$A$2:$A$3001,0)) -> V032
A35: Q50034 | B35: PO10034 | C35: 4184 | D35: 339 | E35: 45388 | F35: Dimension mismatch | G35: =INDEX(PurchaseOrders!$B$2:$B$3001,MATCH(B35,PurchaseOrders!$A$2:$A$3001,0)) -> V001
A36: Q50035 | B36: PO10035 | C36: 757 | D36: 0 | E36: 45521 | G36: =INDEX(PurchaseOrders!$B$2:$B$3001,MATCH(B36,PurchaseOrders!$A$2:$A$3001,0)) -> V035
A37: Q50036 | B37: PO10036 | C37: 448 | D37: 16 | E37: 45335 | F37: Surface finish issue | G37: =INDEX(PurchaseOrders!$B$2:$B$3001,MATCH(B37,PurchaseOrders!$A$2:$A$3001,0)) -> V013
A38: Q50037 | B38: PO10037 | C38: 298 | D38: 2 | E38: 45297 | F38: Surface finish issue | G38: =INDEX(PurchaseOrders!$B$2:$B$3001,MATCH(B38,PurchaseOrders!$A$2:$A$3001,0)) -> V031
A39: Q50038 | B39: PO10038 | C39: 1566 | D39: 72 | E39: 45551 | F39: Wrong specification | G39: =INDEX(PurchaseOrders!$B$2:$B$3001,MATCH(B39,PurchaseOrders!$A$2:$A$3001,0)) -> V014
A40: Q50039 | B40: PO10039 | C40: 3 | D40: 0 | E40: 45014 | G40: =INDEX(PurchaseOrders!$B$2:$B$3001,MATCH(B40,PurchaseOrders!$A$2:$A$3001,0)) -> V041
...

Sheet ShipmentTracking
A1: PO_ID | B1: ShippedDate | C1: CarrierName | D1: Origin | E1: Destination | F1: DelayReason
A2: PO10001 | B2: 45504 | C2: Gati | D2: Mumbai | E2: Delhi NCR | F2: Vendor production delay
A3: PO10002 | B3: 45626 | C3: BlueDart | D3: Coimbatore | E3: Mumbai | F3: Carrier capacity issue
A4: PO10003 | B4: 45059 | C4: TCI Express | D4: Hyderabad | E4: Chennai | F4: Documentation error
A5: PO10004 | B5: 45238 | C5: BlueDart | D5: Surat | E5: Pune
A6: PO10005 | B6: 45411 | C6: TCI Express | D6: Kolkata | E6: Bengaluru
A7: PO10006 | B7: 45130 | C7: DHL | D7: Coimbatore | E7: Hyderabad | F7: Vendor production delay
A8: PO10007 | B8: 45377 | C8: Delhivery | D8: Mumbai | E8: Ahmedabad | F8: Vendor production delay
A9: PO10008 | B9: 45631 | C9: Gati | D9: Hyderabad | E9: Kolkata
A10: PO10009 | B10: 45174 | C10: TCI Express | D10: Pune | E10: Kolkata | F10: Port congestion
A11: PO10010 | B11: 45390 | C11: FedEx | D11: Hyderabad | E11: Delhi NCR | F11: Weather disruption
A12: PO10011 | B12: 45570 | C12: Gati | D12: Bengaluru | E12: Chennai | F12: Documentation error
A13: PO10012 | B13: 45271 | C13: TCI Express | D13: Coimbatore | E13: Bengaluru
A14: PO10013 | B14: 45360 | C14: Safexpress | D14: Surat | E14: Hyderabad
A15: PO10014 | B15: 45108 | C15: BlueDart | D15: Pune | E15: Ahmedabad | F15: Documentation error
A16: PO10015 | B16: 45273 | C16: Gati | D16: Ahmedabad | E16: Surat | F16: Port congestion
A17: PO10016 | B17: 45104 | C17: FedEx | D17: Surat | E17: Coimbatore | F17: Customs delay
A18: PO10017 | B18: 44982 | C18: BlueDart | D18: Delhi NCR | E18: Ahmedabad | F18: Documentation error
A19: PO10018 | B19: 44981 | C19: Delhivery | D19: Delhi NCR | E19: Hyderabad
A20: PO10019 | B20: 45081 | C20: Safexpress | D20: Bengaluru | E20: Ahmedabad | F20: Documentation error
A21: PO10020 | B21: 45056 | C21: BlueDart | D21: Coimbatore | E21: Ahmedabad | F21: Carrier capacity issue
A22: PO10021 | B22: 45627 | C22: TCI Express | D22: Bengaluru | E22: Bengaluru
A23: PO10022 | B23: 45330 | C23: Safexpress | D23: Delhi NCR | E23: Mumbai | F23: Vendor production delay
A24: PO10023 | B24: 45011 | C24: DHL | D24: Delhi NCR | E24: Mumbai
A25: PO10024 | B25: 44977 | C25: DHL | D25: Surat | E25: Surat
A26: PO10025 | B26: 45615 | C26: Safexpress | D26: Pune | E26: Bengaluru | F26: Port congestion
A27: PO10026 | B27: 45307 | C27: DHL | D27: Pune | E27: Hyderabad
A28: PO10027 | B28: 45232 | C28: BlueDart | D28: Chennai | E28: Mumbai | F28: Vendor production delay
A29: PO10028 | B29: 45480 | C29: Delhivery | D29: Pune | E29: Delhi NCR | F29: Weather disruption
A30: PO10029 | B30: 45610 | C30: Gati | D30: Hyderabad | E30: Mumbai
A31: PO10030 | B31: 45649 | C31: FedEx | D31: Mumbai | E31: Surat | F31: Vendor production delay
A32: PO10031 | B32: 45220 | C32: Safexpress | D32: Delhi NCR | E32: Hyderabad | F32: Weather disruption
A33: PO10032 | B33: 45315 | C33: Gati | D33: Hyderabad | E33: Kolkata
A34: PO10033 | B34: 45534 | C34: TCI Express | D34: Surat | E34: Delhi NCR | F34: Customs delay
A35: PO10034 | B35: 45379 | C35: DHL | D35: Surat | E35: Bengaluru | F35: Weather disruption
A36: PO10035 | B36: 45511 | C36: DHL | D36: Ahmedabad | E36: Chennai | F36: Weather disruption
A37: PO10036 | B37: 45319 | C37: Safexpress | D37: Coimbatore | E37: Surat
A38: PO10037 | B38: 45279 | C38: Delhivery | D38: Chennai | E38: Mumbai
A39: PO10038 | B39: 45538 | C39: FedEx | D39: Hyderabad | E39: Mumbai | F39: Weather disruption
A40: PO10039 | B40: 45012 | C40: TCI Express | D40: Bengaluru | E40: Mumbai
...

Sheet DataQualityChecks
A1: Data Quality Checks — PurchaseOrders
A3: Check | B3: Result (count of issues) | C3: Status
A4: Duplicate PO_IDs | B4: =SUMPRODUCT((COUNTIF(PurchaseOrders!A2:A3001,PurchaseOrders!A2:A3001)>1)*1) -> 0 | C4: =IF(B4=0,"OK","REVIEW") -> OK
A5: Blank VendorID | B5: =COUNTBLANK(PurchaseOrders!B2:B3001) -> 0 | C5: =IF(B5=0,"OK","REVIEW") -> OK
A6: Blank OrderDate | B6: =COUNTBLANK(PurchaseOrders!C2:C3001) -> 0 | C6: =IF(B6=0,"OK","REVIEW") -> OK
A7: Blank PromisedDeliveryDate | B7: =COUNTBLANK(PurchaseOrders!D2:D3001) -> 0 | C7: =IF(B7=0,"OK","REVIEW") -> OK
A8: Blank ActualDeliveryDate | B8: =COUNTBLANK(PurchaseOrders!E2:E3001) -> 0 | C8: =IF(B8=0,"OK","REVIEW") -> OK
A9: DeliveredQty > OrderedQty (impossible) | B9: =SUMPRODUCT((PurchaseOrders!G2:G3001>PurchaseOrders!F2:F3001)*1) -> 0 | C9: =IF(B9=0,"OK","REVIEW") -> OK
A10: Negative OrderedQty | B10: =COUNTIF(PurchaseOrders!F2:F3001,"<0") -> 0 | C10: =IF(B10=0,"OK","REVIEW") -> OK
A11: Negative DeliveredQty | B11: =COUNTIF(PurchaseOrders!G2:G3001,"<0") -> 0 | C11: =IF(B11=0,"OK","REVIEW") -> OK
A12: Negative or zero ContractedUnitPrice | B12: =COUNTIF(PurchaseOrders!H2:H3001,"<=0") -> 0 | C12: =IF(B12=0,"OK","REVIEW") -> OK
A13: ActualDeliveryDate before OrderDate (impossible) | B13: =SUMPRODUCT((PurchaseOrders!E2:E3001<PurchaseOrders!C2:C3001)*1) -> 0 | C13: =IF(B13=0,"OK","REVIEW") -> OK
A15: Note: This dataset is synthetic and generated to be clean by design — expect all checks to read OK. In a real vendor dataset, this sheet is where you'd catch and flag broken records before analyzing.

Sheet VendorMetrics
A1: VendorID | B1: VendorName | C1: Category | D1: OrderCount | E1: OnTimePct | F1: AvgDelayDays | G1: AvgFillRatePct | H1: AvgPriceVariancePct | I1: DefectRatePct | J1: DelayRisk | K1: DefectRisk | L1: PriceRisk | M1: FillRisk | N1: DelayRiskNorm | O1: DefectRiskNorm | P1: PriceRiskNorm | Q1: FillRiskNorm | R1: RiskScore | S1: RiskTier | T1: RiskRank | U1: TotalSpend | V1: SupplyRiskLevel | W1: SpendLevel | X1: KraljicQuadrant
A2: =Vendors!A2 -> V001 | B2: =INDEX(Vendors!$B$2:$B$61,MATCH(A2,Vendors!$A$2:$A$61,0)) -> Everest Supplies | C2: =INDEX(Vendors!$C$2:$C$61,MATCH(A2,Vendors!$A$2:$A$61,0)) -> Packaging | D2: =COUNTIF(PurchaseOrders!$B$2:$B$3001,A2) -> 53 | E2: =IFERROR(AVERAGEIFS(PurchaseOrders!$K$2:$K$3001,PurchaseOrders!$B$2:$B$3001,A2),0) -> 0.64150943 | F2: =IFERROR(AVERAGEIFS(PurchaseOrders!$J$2:$J$3001,PurchaseOrders!$B$2:$B$3001,A2),0) -> -0.20754717 | G2: =IFERROR(AVERAGEIFS(PurchaseOrders!$L$2:$L$3001,PurchaseOrders!$B$2:$B$3001,A2),0) -> 0.90290722 | H2: =IFERROR(AVERAGEIFS(PurchaseOrders!$M$2:$M$3001,PurchaseOrders!$B$2:$B$3001,A2),0) -> 0.0090013183 | I2: =IFERROR(SUMIFS(QualityInspections!$D$2:$D$3001,QualityInspections!$G$2:$G$3001,A2)/SUMIFS(QualityInspections!$C$2:$C$3001,QualityInspections!$G$2:$G$3001,A2),0) -> 0.066034588 | J2: =1-E2 -> 0.35849057 | K2: =I2 -> 0.066034588 | L2: =MAX(H2,0) -> 0.0090013183 | M2: =1-G2 -> 0.097092784 | N2: =IFERROR((J2-MIN($J$2:$J$61))/(MAX($J$2:$J$61)-MIN($J$2:$J$61))*100,0) -> 27.101201 | O2: =IFERROR((K2-MIN($K$2:$K$61))/(MAX($K$2:$K$61)-MIN($K$2:$K$61))*100,0) -> 26.737918 | P2: =IFERROR((L2-MIN($L$2:$L$61))/(MAX($L$2:$L$61)-MIN($L$2:$L$61))*100,0) -> 7.9550137 | Q2: =IFERROR((M2-MIN($M$2:$M$61))/(MAX($M$2:$M$61)-MIN($M$2:$M$61))*100,0) -> 65.975575 | R2: =0.35*N2+0.3*O2+0.2*P2+0.15*Q2 -> 28.994135 | S2: =IF(R2>=65,"High",IF(R2>=40,"Medium","Low")) -> Low | T2: =RANK(R2,$R$2:$R$61,0) -> 41 | U2: =SUMIFS(PurchaseOrders!$N$2:$N$3001,PurchaseOrders!$B$2:$B$3001,A2) -> 4228138.2 | V2: =IF(R2>=MEDIAN($R$2:$R$61),"High Risk","Low Risk") -> Low Risk | W2: =IF(U2>=MEDIAN($U$2:$U$61),"High Spend","Low Spend") -> Low Spend | X2: =IF(AND(V2="High Risk",W2="High Spend"),"Strategic",IF(AND(V2="High Risk",W2="Low Spend"),"Bottleneck",IF(AND(V2="Low Risk",W2="High Spend"),"Leverage","Non-Critical"))) -> Non-Critical
A3: =Vendors!A3 -> V002 | B3: =INDEX(Vendors!$B$2:$B$61,MATCH(A3,Vendors!$A$2:$A$61,0)) -> Global Enterprises | C3: =INDEX(Vendors!$C$2:$C$61,MATCH(A3,Vendors!$A$2:$A$61,0)) -> Packaging | D3: =COUNTIF(PurchaseOrders!$B$2:$B$3001,A3) -> 61 | E3: =IFERROR(AVERAGEIFS(PurchaseOrders!$K$2:$K$3001,PurchaseOrders!$B$2:$B$3001,A3),0) -> 0.50819672 | F3: =IFERROR(AVERAGEIFS(PurchaseOrders!$J$2:$J$3001,PurchaseOrders!$B$2:$B$3001,A3),0) -> 0.37704918 | G3: =IFERROR(AVERAGEIFS(PurchaseOrders!$L$2:$L$3001,PurchaseOrders!$B$2:$B$3001,A3),0) -> 0.98562279 | H3: =IFERROR(AVERAGEIFS(PurchaseOrders!$M$2:$M$3001,PurchaseOrders!$B$2:$B$3001,A3),0) -> -0.033906294 | I3: =IFERROR(SUMIFS(QualityInspections!$D$2:$D$3001,QualityInspections!$G$2:$G$3001,A3)/SUMIFS(QualityInspections!$C$2:$C$3001,QualityInspections!$G$2:$G$3001,A3),0) -> 0.031105884 | J3: =1-E3 -> 0.49180328 | K3: =I3 -> 0.031105884 | L3: =MAX(H3,0) -> 0 | M3: =1-G3 -> 0.014377205 | N3: =IFERROR((J3-MIN($J$2:$J$61))/(MAX($J$2:$J$61)-MIN($J$2:$J$61))*100,0) -> 42.250373 | O3: =IFERROR((K3-MIN($K$2:$K$61))/(MAX($K$2:$K$61)-MIN($K$2:$K$61))*100,0) -> 10.48359 | P3: =IFERROR((L3-MIN($L$2:$L$61))/(MAX($L$2:$L$61)-MIN($L$2:$L$61))*100,0) -> 0 | Q3: =IFERROR((M3-MIN($M$2:$M$61))/(MAX($M$2:$M$61)-MIN($M$2:$M$61))*100,0) -> 7.2248233 | R3: =0.35*N3+0.3*O3+0.2*P3+0.15*Q3 -> 19.016431 | S3: =IF(R3>=65,"High",IF(R3>=40,"Medium","Low")) -> Low | T3: =RANK(R3,$R$2:$R$61,0) -> 55 | U3: =SUMIFS(PurchaseOrders!$N$2:$N$3001,PurchaseOrders!$B$2:$B$3001,A3) -> 3710902.6 | V3: =IF(R3>=MEDIAN($R$2:$R$61),"High Risk","Low Risk") -> Low Risk | W3: =IF(U3>=MEDIAN($U$2:$U$61),"High Spend","Low Spend") -> Low Spend | X3: =IF(AND(V3="High Risk",W3="High Spend"),"Strategic",IF(AND(V3="High Risk",W3="Low Spend"),"Bottleneck",IF(AND(V3="Low Risk",W3="High Spend"),"Leverage","Non-Critical"))) -> Non-Critical
A4: =Vendors!A4 -> V003 | B4: =INDEX(Vendors!$B$2:$B$61,MATCH(A4,Vendors!$A$2:$A$61,0)) -> Vertex Logistics | C4: =INDEX(Vendors!$C$2:$C$61,MATCH(A4,Vendors!$A$2:$A$61,0)) -> Packaging | D4: =COUNTIF(PurchaseOrders!$B$2:$B$3001,A4) -> 57 | E4: =IFERROR(AVERAGEIFS(PurchaseOrders!$K$2:$K$3001,PurchaseOrders!$B$2:$B$3001,A4),0) -> 0.63157895 | F4: =IFERROR(AVERAGEIFS(PurchaseOrders!$J$2:$J$3001,PurchaseOrders!$B$2:$B$3001,A4),0) -> -0.21052632 | G4: =IFERROR(AVERAGEIFS(PurchaseOrders!$L$2:$L$3001,PurchaseOrders!$B$2:$B$3001,A4),0) -> 0.99068624 | H4: =IFERROR(AVERAGEIFS(PurchaseOrders!$M$2:$M$3001,PurchaseOrders!$B$2:$B$3001,A4),0) -> -0.019058853 | I4: =IFERROR(SUMIFS(QualityInspections!$D$2:$D$3001,QualityInspections!$G$2:$G$3001,A4)/SUMIFS(QualityInspections!$C$2:$C$3001,QualityInspections!$G$2:$G$3001,A4),0) -> 0.044161063 | J4: =1-E4 -> 0.36842105 | K4: =I4 -> 0.044161063 | L4: =MAX(H4,0) -> 0 | M4: =1-G4 -> 0.0093137592 | N4: =IFERROR((J4-MIN($J$2:$J$61))/(MAX($J$2:$J$61)-MIN($J$2:$J$61))*100,0) -> 28.229665 | O4: =IFERROR((K4-MIN($K$2:$K$61))/(MAX($K$2:$K$61)-MIN($K$2:$K$61))*100,0) -> 16.558913 | P4: =IFERROR((L4-MIN($L$2:$L$61))/(MAX($L$2:$L$61)-MIN($L$2:$L$61))*100,0) -> 0 | Q4: =IFERROR((M4-MIN($M$2:$M$61))/(MAX($M$2:$M$61)-MIN($M$2:$M$61))*100,0) -> 3.6283876 | R4: =0.35*N4+0.3*O4+0.2*P4+0.15*Q4 -> 15.392315 | S4: =IF(R4>=65,"High",IF(R4>=40,"Medium","Low")) -> Low | T4: =RANK(R4,$R$2:$R$61,0) -> 57 | U4: =SUMIFS(PurchaseOrders!$N$2:$N$3001,PurchaseOrders!$B$2:$B$3001,A4) -> 6860856.4 | V4: =IF(R4>=MEDIAN($R$2:$R$61),"High Risk","Low Risk") -> Low Risk | W4: =IF(U4>=MEDIAN($U$2:$U$61),"High Spend","Low Spend") -> High Spend | X4: =IF(AND(V4="High Risk",W4="High Spend"),"Strategic",IF(AND(V4="High Risk",W4="Low Spend"),"Bottleneck",IF(AND(V4="Low Risk",W4="High Spend"),"Leverage","Non-Critical"))) -> Leverage
A5: =Vendors!A5 -> V004 | B5: =INDEX(Vendors!$B$2:$B$61,MATCH(A5,Vendors!$A$2:$A$61,0)) -> Everest Manufacturing | C5: =INDEX(Vendors!$C$2:$C$61,MATCH(A5,Vendors!$A$2:$A$61,0)) -> Electronics | D5: =COUNTIF(PurchaseOrders!$B$2:$B$3001,A5) -> 48 | E5: =IFERROR(AVERAGEIFS(PurchaseOrders!$K$2:$K$3001,PurchaseOrders!$B$2:$B$3001,A5),0) -> 0.33333333 | F5: =IFERROR(AVERAGEIFS(PurchaseOrders!$J$2:$J$3001,PurchaseOrders!$B$2:$B$3001,A5),0) -> 1.5 | G5: =IFERROR(AVERAGEIFS(PurchaseOrders!$L$2:$L$3001,PurchaseOrders!$B$2:$B$3001,A5),0) -> 0.97048726 | H5: =IFERROR(AVERAGEIFS(PurchaseOrders!$M$2:$M$3001,PurchaseOrders!$B$2:$B$3001,A5),0) -> 0.0061620384 | I5: =IFERROR(SUMIFS(QualityInspections!$D$2:$D$3001,QualityInspections!$G$2:$G$3001,A5)/SUMIFS(QualityInspections!$C$2:$C$3001,QualityInspections!$G$2:$G$3001,A5),0) -> 0.054181296 | J5: =1-E5 -> 0.66666667 | K5: =I5 -> 0.054181296 | L5: =MAX(H5,0) -> 0.0061620384 | M5: =1-G5 -> 0.029512743 | N5: =IFERROR((J5-MIN($J$2:$J$61))/(MAX($J$2:$J$61)-MIN($J$2:$J$61))*100,0) -> 62.121212 | O5: =IFERROR((K5-MIN($K$2:$K$61))/(MAX($K$2:$K$61)-MIN($K$2:$K$61))*100,0) -> 21.221902 | P5: =IFERROR((L5-MIN($L$2:$L$61))/(MAX($L$2:$L$61)-MIN($L$2:$L$61))*100,0) -> 5.445769 | Q5: =IFERROR((M5-MIN($M$2:$M$61))/(MAX($M$2:$M$61)-MIN($M$2:$M$61))*100,0) -> 17.975207 | R5: =0.35*N5+0.3*O5+0.2*P5+0.15*Q5 -> 31.89443 | S5: =IF(R5>=65,"High",IF(R5>=40,"Medium","Low")) -> Low | T5: =RANK(R5,$R$2:$R$61,0) -> 36 | U5: =SUMIFS(PurchaseOrders!$N$2:$N$3001,PurchaseOrders!$B$2:$B$3001,A5) -> 16649782 | V5: =IF(R5>=MEDIAN($R$2:$R$61),"High Risk","Low Risk") -> Low Risk | W5: =IF(U5>=MEDIAN($U$2:$U$61),"High Spend","Low Spend") -> High Spend | X5: =IF(AND(V5="High Risk",W5="High Spend"),"Strategic",IF(AND(V5="High Risk",W5="Low Spend"),"Bottleneck",IF(AND(V5="Low Risk",W5="High Spend"),"Leverage","Non-Critical"))) -> Leverage
A6: =Vendors!A6 -> V005 | B6: =INDEX(Vendors!$B$2:$B$61,MATCH(A6,Vendors!$A$2:$A$61,0)) -> Kiran Industries | C6: =INDEX(Vendors!$C$2:$C$61,MATCH(A6,Vendors!$A$2:$A$61,0)) -> Raw Materials | D6: =COUNTIF(PurchaseOrders!$B$2:$B$3001,A6) -> 40 | E6: =IFERROR(AVERAGEIFS(PurchaseOrders!$K$2:$K$3001,PurchaseOrders!$B$2:$B$3001,A6),0) -> 0.775 | F6: =IFERROR(AVERAGEIFS(PurchaseOrders!$J$2:$J$3001,PurchaseOrders!$B$2:$B$3001,A6),0) -> -0.775 | G6: =IFERROR(AVERAGEIFS(PurchaseOrders!$L$2:$L$3001,PurchaseOrders!$B$2:$B$3001,A6),0) -> 0.98095263 | H6: =IFERROR(AVERAGEIFS(PurchaseOrders!$M$2:$M$3001,PurchaseOrders!$B$2:$B$3001,A6),0) -> 0.0059078188 | I6: =IFERROR(SUMIFS(QualityInspections!$D$2:$D$3001,QualityInspections!$G$2:$G$3001,A6)/SUMIFS(QualityInspections!$C$2:$C$3001,QualityInspections!$G$2:$G$3001,A6),0) -> 0.074099469 | J6: =1-E6 -> 0.225 | K6: =I6 -> 0.074099469 | L6: =MAX(H6,0) -> 0.0059078188 | M6: =1-G6 -> 0.019047368 | N6: =IFERROR((J6-MIN($J$2:$J$61))/(MAX($J$2:$J$61)-MIN($J$2:$J$61))*100,0) -> 11.931818 | O6: =IFERROR((K6-MIN($K$2:$K$61))/(MAX($K$2:$K$61)-MIN($K$2:$K$61))*100,0) -> 30.490969 | P6: =IFERROR((L6-MIN($L$2:$L$61))/(MAX($L$2:$L$61)-MIN($L$2:$L$61))*100,0) -> 5.2210996 | Q6: =IFERROR((M6-MIN($M$2:$M$61))/(MAX($M$2:$M$61)-MIN($M$2:$M$61))*100,0) -> 10.54192 | R6: =0.35*N6+0.3*O6+0.2*P6+0.15*Q6 -> 15.948935 | S6: =IF(R6>=65,"High",IF(R6>=40,"Medium","Low")) -> Low | T6: =RANK(R6,$R$2:$R$61,0) -> 56 | U6: =SUMIFS(PurchaseOrders!$N$2:$N$3001,PurchaseOrders!$B$2:$B$3001,A6) -> 9405257.2 | V6: =IF(R6>=MEDIAN($R$2:$R$61),"High Risk","Low Risk") -> Low Risk | W6: =IF(U6>=MEDIAN($U$2:$U$61),"High Spend","Low Spend") -> High Spend | X6: =IF(AND(V6="High Risk",W6="High Spend"),"Strategic",IF(AND(V6="High Risk",W6="Low Spend"),"Bottleneck",IF(AND(V6="Low Risk",W6="High Spend"),"Leverage","Non-Critical"))) -> Leverage
A7: =Vendors!A7 -> V006 | B7: =INDEX(Vendors!$B$2:$B$61,MATCH(A7,Vendors!$A$2:$A$61,0)) -> Apex Systems | C7: =INDEX(Vendors!$C$2:$C$61,MATCH(A7,Vendors!$A$2:$A$61,0)) -> Electronics | D7: =COUNTIF(PurchaseOrders!$B$2:$B$3001,A7) -> 38 | E7: =IFERROR(AVERAGEIFS(PurchaseOrders!$K$2:$K$3001,PurchaseOrders!$B$2:$B$3001,A7),0) -> 0.84210526 | F7: =IFERROR(AVERAGEIFS(PurchaseOrders!$J$2:$J$3001,PurchaseOrders!$B$2:$B$3001,A7),0) -> -1.5 | G7: =IFERROR(AVERAGEIFS(PurchaseOrders!$L$2:$L$3001,PurchaseOrders!$B$2:$B$3001,A7),0) -> 0.98428313 | H7: =IFERROR(AVERAGEIFS(PurchaseOrders!$M$2:$M$3001,PurchaseOrders!$B$2:$B$3001,A7),0) -> 0.052203644 | I7: =IFERROR(SUMIFS(QualityInspections!$D$2:$D$3001,QualityInspections!$G$2:$G$3001,A7)/SUMIFS(QualityInspections!$C$2:$C$3001,QualityInspections!$G$2:$G$3001,A7),0) -> 0.031902491 | J7: =1-E7 -> 0.15789474 | K7: =I7 -> 0.031902491 | L7: =MAX(H7,0) -> 0.052203644 | M7: =1-G7 -> 0.015716866 | N7: =IFERROR((J7-MIN($J$2:$J$61))/(MAX($J$2:$J$61)-MIN($J$2:$J$61))*100,0) -> 4.3062201 | O7: =IFERROR((K7-MIN($K$2:$K$61))/(MAX($K$2:$K$61)-MIN($K$2:$K$61))*100,0) -> 10.854296 | P7: =IFERROR((L7-MIN($L$2:$L$61))/(MAX($L$2:$L$61)-MIN($L$2:$L$61))*100,0) -> 46.135542 | Q7: =IFERROR((M7-MIN($M$2:$M$61))/(MAX($M$2:$M$61)-MIN($M$2:$M$61))*100,0) -> 8.1763501 | R7: =0.35*N7+0.3*O7+0.2*P7+0.15*Q7 -> 15.217027 | S7: =IF(R7>=65,"High",IF(R7>=40,"Medium","Low")) -> Low | T7: =RANK(R7,$R$2:$R$61,0) -> 58 | U7: =SUMIFS(PurchaseOrders!$N$2:$N$3001,PurchaseOrders!$B$2:$B$3001,A7) -> 7008212.6 | V7: =IF(R7>=MEDIAN($R$2:$R$61),"High Risk","Low Risk") -> Low Risk | W7: =IF(U7>=MEDIAN($U$2:$U$61),"High Spend","Low Spend") -> High Spend | X7: =IF(AND(V7="High Risk",W7="High Spend"),"Strategic",IF(AND(V7="High Risk",W7="Low Spend"),"Bottleneck",IF(AND(V7="Low Risk",W7="High Spend"),"Leverage","Non-Critical"))) -> Leverage
A8: =Vendors!A8 -> V007 | B8: =INDEX(Vendors!$B$2:$B$61,MATCH(A8,Vendors!$A$2:$A$61,0)) -> Kingfisher Supplies | C8: =INDEX(Vendors!$C$2:$C$61,MATCH(A8,Vendors!$A$2:$A$61,0)) -> Raw Materials | D8: =COUNTIF(PurchaseOrders!$B$2:$B$3001,A8) -> 54 | E8: =IFERROR(AVERAGEIFS(PurchaseOrders!$K$2:$K$3001,PurchaseOrders!$B$2:$B$3001,A8),0) -> 0 | F8: =IFERROR(AVERAGEIFS(PurchaseOrders!$J$2:$J$3001,PurchaseOrders!$B$2:$B$3001,A8),0) -> 6.7592593 | G8: =IFERROR(AVERAGEIFS(PurchaseOrders!$L$2:$L$3001,PurchaseOrders!$B$2:$B$3001,A8),0) -> 0.855004 | H8: =IFERROR(AVERAGEIFS(PurchaseOrders!$M$2:$M$3001,PurchaseOrders!$B$2:$B$3001,A8),0) -> 0.022545513 | I8: =IFERROR(SUMIFS(QualityInspections!$D$2:$D$3001,QualityInspections!$G$2:$G$3001,A8)/SUMIFS(QualityInspections!$C$2:$C$3001,QualityInspections!$G$2:$G$3001,A8),0) -> 0.068939748 | J8: =1-E8 -> 1 | K8: =I8 -> 0.068939748 | L8: =MAX(H8,0) -> 0.022545513 | M8: =1-G8 -> 0.144996 | N8: =IFERROR((J8-MIN($J$2:$J$61))/(MAX($J$2:$J$61)-MIN($J$2:$J$61))*100,0) -> 100 | O8: =IFERROR((K8-MIN($K$2:$K$61))/(MAX($K$2:$K$61)-MIN($K$2:$K$61))*100,0) -> 28.089855 | P8: =IFERROR((L8-MIN($L$2:$L$61))/(MAX($L$2:$L$61)-MIN($L$2:$L$61))*100,0) -> 19.924844 | Q8: =IFERROR((M8-MIN($M$2:$M$61))/(MAX($M$2:$M$61)-MIN($M$2:$M$61))*100,0) -> 100 | R8: =0.35*N8+0.3*O8+0.2*P8+0.15*Q8 -> 62.411925 | S8: =IF(R8>=65,"High",IF(R8>=40,"Medium","Low")) -> Medium | T8: =RANK(R8,$R$2:$R$61,0) -> 3 | U8: =SUMIFS(PurchaseOrders!$N$2:$N$3001,PurchaseOrders!$B$2:$B$3001,A8) -> 9306915.3 | V8: =IF(R8>=MEDIAN($R$2:$R$61),"High Risk","Low Risk") -> High Risk | W8: =IF(U8>=MEDIAN($U$2:$U$61),"High Spend","Low Spend") -> High Spend | X8: =IF(AND(V8="High Risk",W8="High Spend"),"Strategic",IF(AND(V8="High Risk",W8="Low Spend"),"Bottleneck",IF(AND(V8="Low Risk",W8="High Spend"),"Leverage","Non-Critical"))) -> Strategic
A9: =Vendors!A9 -> V008 | B9: =INDEX(Vendors!$B$2:$B$61,MATCH(A9,Vendors!$A$2:$A$61,0)) -> Jyoti Supplies | C9: =INDEX(Vendors!$C$2:$C$61,MATCH(A9,Vendors!$A$2:$A$61,0)) -> Electronics | D9: =COUNTIF(PurchaseOrders!$B$2:$B$3001,A9) -> 47 | E9: =IFERROR(AVERAGEIFS(PurchaseOrders!$K$2:$K$3001,PurchaseOrders!$B$2:$B$3001,A9),0) -> 0.63829787 | F9: =IFERROR(AVERAGEIFS(PurchaseOrders!$J$2:$J$3001,PurchaseOrders!$B$2:$B$3001,A9),0) -> -0.74468085 | G9: =IFERROR(AVERAGEIFS(PurchaseOrders!$L$2:$L$3001,PurchaseOrders!$B$2:$B$3001,A9),0) -> 0.95302074 | H9: =IFERROR(AVERAGEIFS(PurchaseOrders!$M$2:$M$3001,PurchaseOrders!$B$2:$B$3001,A9),0) -> -0.034674209 | I9: =IFERROR(SUMIFS(QualityInspections!$D$2:$D$3001,QualityInspections!$G$2:$G$3001,A9)/SUMIFS(QualityInspections!$C$2:$C$3001,QualityInspections!$G$2:$G$3001,A9),0) -> 0.0085778419 | J9: =1-E9 -> 0.36170213 | K9: =I9 -> 0.0085778419 | L9: =MAX(H9,0) -> 0 | M9: =1-G9 -> 0.046979262 | N9: =IFERROR((J9-MIN($J$2:$J$61))/(MAX($J$2:$J$61)-MIN($J$2:$J$61))*100,0) -> 27.466151 | O9: =IFERROR((K9-MIN($K$2:$K$61))/(MAX($K$2:$K$61)-MIN($K$2:$K$61))*100,0) -> 0 | P9: =IFERROR((L9-MIN($L$2:$L$61))/(MAX($L$2:$L$61)-MIN($L$2:$L$61))*100,0) -> 0 | Q9: =IFERROR((M9-MIN($M$2:$M$61))/(MAX($M$2:$M$61)-MIN($M$2:$M$61))*100,0) -> 30.381227 | R9: =0.35*N9+0.3*O9+0.2*P9+0.15*Q9 -> 14.170337 | S9: =IF(R9>=65,"High",IF(R9>=40,"Medium","Low")) -> Low | T9: =RANK(R9,$R$2:$R$61,0) -> 59 | U9: =SUMIFS(PurchaseOrders!$N$2:$N$3001,PurchaseOrders!$B$2:$B$3001,A9) -> 7183322.3 | V9: =IF(R9>=MEDIAN($R$2:$R$61),"High Risk","Low Risk") -> Low Risk | W9: =IF(U9>=MEDIAN($U$2:$U$61),"High Spend","Low Spend") -> High Spend | X9: =IF(AND(V9="High Risk",W9="High Spend"),"Strategic",IF(AND(V9="High Risk",W9="Low Spend"),"Bottleneck",IF(AND(V9="Low Risk",W9="High Spend"),"Leverage","Non-Critical"))) -> Leverage
A10: =Vendors!A10 -> V009 | B10: =INDEX(Vendors!$B$2:$B$61,MATCH(A10,Vendors!$A$2:$A$61,0)) -> Zenith Traders | C10: =INDEX(Vendors!$C$2:$C$61,MATCH(A10,Vendors!$A$2:$A$61,0)) -> MRO/Spares | D10: =COUNTIF(PurchaseOrders!$B$2:$B$3001,A10) -> 64 | E10: =IFERROR(AVERAGEIFS(PurchaseOrders!$K$2:$K$3001,PurchaseOrders!$B$2:$B$3001,A10),0) -> 0.71875 | F10: =IFERROR(AVERAGEIFS(PurchaseOrders!$J$2:$J$3001,PurchaseOrders!$B$2:$B$3001,A10),0) -> -0.625 | G10: =IFERROR(AVERAGEIFS(PurchaseOrders!$L$2:$L$3001,PurchaseOrders!$B$2:$B$3001,A10),0) -> 0.98044294 | H10: =IFERROR(AVERAGEIFS(PurchaseOrders!$M$2:$M$3001,PurchaseOrders!$B$2:$B$3001,A10),0) -> 0.031026588 | I10: =IFERROR(SUMIFS(QualityInspections!$D$2:$D$3001,QualityInspections!$G$2:$G$3001,A10)/SUMIFS(QualityInspections!$C$2:$C$3001,QualityInspections!$G$2:$G$3001,A10),0) -> 0.088443151 | J10: =1-E10 -> 0.28125 | K10: =I10 -> 0.088443151 | L10: =MAX(H10,0) -> 0.031026588 | M10: =1-G10 -> 0.019557056 | N10: =IFERROR((J10-MIN($J$2:$J$61))/(MAX($J$2:$J$61)-MIN($J$2:$J$61))*100,0) -> 18.323864 | O10: =IFERROR((K10-MIN($K$2:$K$61))/(MAX($K$2:$K$61)-MIN($K$2:$K$61))*100,0) -> 37.165907 | P10: =IFERROR((L10-MIN($L$2:$L$61))/(MAX($L$2:$L$61)-MIN($L$2:$L$61))*100,0) -> 27.420088 | Q10: =IFERROR((M10-MIN($M$2:$M$61))/(MAX($M$2:$M$61)-MIN($M$2:$M$61))*100,0) -> 10.903938 | R10: =0.35*N10+0.3*O10+0.2*P10+0.15*Q10 -> 24.682733 | S10: =IF(R10>=65,"High",IF(R10>=40,"Medium","Low")) -> Low | T10: =RANK(R10,$R$2:$R$61,0) -> 47 | U10: =SUMIFS(PurchaseOrders!$N$2:$N$3001,PurchaseOrders!$B$2:$B$3001,A10) -> 1347400.8 | V10: =IF(R10>=MEDIAN($R$2:$R$61),"High Risk","Low Risk") -> Low Risk | W10: =IF(U10>=MEDIAN($U$2:$U$61),"High Spend","Low Spend") -> Low Spend | X10: =IF(AND(V10="High Risk",W10="High Spend"),"Strategic",IF(AND(V10="High Risk",W10="Low Spend"),"Bottleneck",IF(AND(V10="Low Risk",W10="High Spend"),"Leverage","Non-Critical"))) -> Non-Critical
A11: =Vendors!A11 -> V010 | B11: =INDEX(Vendors!$B$2:$B$61,MATCH(A11,Vendors!$A$2:$A$61,0)) -> Precision Enterprises | C11: =INDEX(Vendors!$C$2:$C$61,MATCH(A11,Vendors!$A$2:$A$61,0)) -> Raw Materials | D11: =COUNTIF(PurchaseOrders!$B$2:$B$3001,A11) -> 48 | E11: =IFERROR(AVERAGEIFS(PurchaseOrders!$K$2:$K$3001,PurchaseOrders!$B$2:$B$3001,A11),0) -> 0.0625 | F11: =IFERROR(AVERAGEIFS(PurchaseOrders!$J$2:$J$3001,PurchaseOrders!$B$2:$B$3001,A11),0) -> 6 | G11: =IFERROR(AVERAGEIFS(PurchaseOrders!$L$2:$L$3001,PurchaseOrders!$B$2:$B$3001,A11),0) -> 0.97802304 | H11: =IFERROR(AVERAGEIFS(PurchaseOrders!$M$2:$M$3001,PurchaseOrders!$B$2:$B$3001,A11),0) -> -0.00023081339 | I11: =IFERROR(SUMIFS(QualityInspections!$D$2:$D$3001,QualityInspections!$G$2:$G$3001,A11)/SUMIFS(QualityInspections!$C$2:$C$3001,QualityInspections!$G$2:$G$3001,A11),0) -> 0.032220875 | J11: =1-E11 -> 0.9375 | K11: =I11 -> 0.032220875 | L11: =MAX(H11,0) -> 0 | M11: =1-G11 -> 0.021976956 | N11: =IFERROR((J11-MIN($J$2:$J$61))/(MAX($J$2:$J$61)-MIN($J$2:$J$61))*100,0) -> 92.897727 | O11: =IFERROR((K11-MIN($K$2:$K$61))/(MAX($K$2:$K$61)-MIN($K$2:$K$61))*100,0) -> 11.002459 | P11: =IFERROR((L11-MIN($L$2:$L$61))/(MAX($L$2:$L$61)-MIN($L$2:$L$61))*100,0) -> 0 | Q11: =IFERROR((M11-MIN($M$2:$M$61))/(MAX($M$2:$M$61)-MIN($M$2:$M$61))*100,0) -> 12.622731 | R11: =0.35*N11+0.3*O11+0.2*P11+0.15*Q11 -> 37.708352 | S11: =IF(R11>=65,"High",IF(R11>=40,"Medium","Low")) -> Low | T11: =RANK(R11,$R$2:$R$61,0) -> 29 | U11: =SUMIFS(PurchaseOrders!$N$2:$N$3001,PurchaseOrders!$B$2:$B$3001,A11) -> 5400464.5 | V11: =IF(R11>=MEDIAN($R$2:$R$61),"High Risk","Low Risk") -> High Risk | W11: =IF(U11>=MEDIAN($U$2:$U$61),"High Spend","Low Spend") -> Low Spend | X11: =IF(AND(V11="High Risk",W11="High Spend"),"Strategic",IF(AND(V11="High Risk",W11="Low Spend"),"Bottleneck",IF(AND(V11="Low Risk",W11="High Spend"),"Leverage","Non-Critical"))) -> Bottleneck
A12: =Vendors!A12 -> V011 | B12: =INDEX(Vendors!$B$2:$B$61,MATCH(A12,Vendors!$A$2:$A$61,0)) -> Zenith Pvt Ltd | C12: =INDEX(Vendors!$C$2:$C$61,MATCH(A12,Vendors!$A$2:$A$61,0)) -> Raw Materials | D12: =COUNTIF(PurchaseOrders!$B$2:$B$3001,A12) -> 46 | E12: =IFERROR(AVERAGEIFS(PurchaseOrders!$K$2:$K$3001,PurchaseOrders!$B$2:$B$3001,A12),0) -> 0.043478261 | F12: =IFERROR(AVERAGEIFS(PurchaseOrders!$J$2:$J$3001,PurchaseOrders!$B$2:$B$3001,A12),0) -> 8.1086957 | G12: =IFERROR(AVERAGEIFS(PurchaseOrders!$L$2:$L$3001,PurchaseOrders!$B$2:$B$3001,A12),0) -> 0.92559996 | H12: =IFERROR(AVERAGEIFS(PurchaseOrders!$M$2:$M$3001,PurchaseOrders!$B$2:$B$3001,A12),0) -> 0.064226529 | I12: =IFERROR(SUMIFS(QualityInspections!$D$2:$D$3001,QualityInspections!$G$2:$G$3001,A12)/SUMIFS(QualityInspections!$C$2:$C$3001,QualityInspections!$G$2:$G$3001,A12),0) -> 0.022309404 | J12: =1-E12 -> 0.95652174 | K12: =I12 -> 0.022309404 | L12: =MAX(H12,0) -> 0.064226529 | M12: =1-G12 -> 0.07440004 | N12: =IFERROR((J12-MIN($J$2:$J$61))/(MAX($J$2:$J$61)-MIN($J$2:$J$61))*100,0) -> 95.059289 | O12: =IFERROR((K12-MIN($K$2:$K$61))/(MAX($K$2:$K$61)-MIN($K$2:$K$61))*100,0) -> 6.390083 | P12: =IFERROR((L12-MIN($L$2:$L$61))/(MAX($L$2:$L$61)-MIN($L$2:$L$61))*100,0) -> 56.760899 | Q12: =IFERROR((M12-MIN($M$2:$M$61))/(MAX($M$2:$M$61)-MIN($M$2:$M$61))*100,0) -> 49.857501 | R12: =0.35*N12+0.3*O12+0.2*P12+0.15*Q12 -> 54.018581 | S12: =IF(R12>=65,"High",IF(R12>=40,"Medium","Low")) -> Medium | T12: =RANK(R12,$R$2:$R$61,0) -> 9 | U12: =SUMIFS(PurchaseOrders!$N$2:$N$3001,PurchaseOrders!$B$2:$B$3001,A12) -> 13048708 | V12: =IF(R12>=MEDIAN($R$2:$R$61),"High Risk","Low Risk") -> High Risk | W12: =IF(U12>=MEDIAN($U$2:$U$61),"High Spend","Low Spend") -> High Spend | X12: =IF(AND(V12="High Risk",W12="High Spend"),"Strategic",IF(AND(V12="High Risk",W12="Low Spend"),"Bottleneck",IF(AND(V12="Low Risk",W12="High Spend"),"Leverage","Non-Critical"))) -> Strategic
A13: =Vendors!A13 -> V012 | B13: =INDEX(Vendors!$B$2:$B$61,MATCH(A13,Vendors!$A$2:$A$61,0)) -> Jupiter Systems | C13: =INDEX(Vendors!$C$2:$C$61,MATCH(A13,Vendors!$A$2:$A$61,0)) -> Electronics | D13: =COUNTIF(PurchaseOrders!$B$2:$B$3001,A13) -> 44 | E13: =IFERROR(AVERAGEIFS(PurchaseOrders!$K$2:$K$3001,PurchaseOrders!$B$2:$B$3001,A13),0) -> 0.56818182 | F13: =IFERROR(AVERAGEIFS(PurchaseOrders!$J$2:$J$3001,PurchaseOrders!$B$2:$B$3001,A13),0) -> -0.34090909 | G13: =IFERROR(AVERAGEIFS(PurchaseOrders!$L$2:$L$3001,PurchaseOrders!$B$2:$B$3001,A13),0) -> 0.99080961 | H13: =IFERROR(AVERAGEIFS(PurchaseOrders!$M$2:$M$3001,PurchaseOrders!$B$2:$B$3001,A13),0) -> 0.00209633 | I13: =IFERROR(SUMIFS(QualityInspections!$D$2:$D$3001,QualityInspections!$G$2:$G$3001,A13)/SUMIFS(QualityInspections!$C$2:$C$3001,QualityInspections!$G$2:$G$3001,A13),0) -> 0.072078907 | J13: =1-E13 -> 0.43181818 | K13: =I13 -> 0.072078907 | L13: =MAX(H13,0) -> 0.00209633 | M13: =1-G13 -> 0.0091903855 | N13: =IFERROR((J13-MIN($J$2:$J$61))/(MAX($J$2:$J$61)-MIN($J$2:$J$61))*100,0) -> 35.433884 | O13: =IFERROR((K13-MIN($K$2:$K$61))/(MAX($K$2:$K$61)-MIN($K$2:$K$61))*100,0) -> 29.550686 | P13: =IFERROR((L13-MIN($L$2:$L$61))/(MAX($L$2:$L$61)-MIN($L$2:$L$61))*100,0) -> 1.8526546 | Q13: =IFERROR((M13-MIN($M$2:$M$61))/(MAX($M$2:$M$61)-MIN($M$2:$M$61))*100,0) -> 3.5407584 | R13: =0.35*N13+0.3*O13+0.2*P13+0.15*Q13 -> 22.16871 | S13: =IF(R13>=65,"High",IF(R13>=40,"Medium","Low")) -> Low | T13: =RANK(R13,$R$2:$R$61,0) -> 52 | U13: =SUMIFS(PurchaseOrders!$N$2:$N$3001,PurchaseOrders!$B$2:$B$3001,A13) -> 16245988 | V13: =IF(R13>=MEDIAN($R$2:$R$61),"High Risk","Low Risk") -> Low Risk | W13: =IF(U13>=MEDIAN($U$2:$U$61),"High Spend","Low Spend") -> High Spend | X13: =IF(AND(V13="High Risk",W13="High Spend"),"Strategic",IF(AND(V13="High Risk",W13="Low Spend"),"Bottleneck",IF(AND(V13="Low Risk",W13="High Spend"),"Leverage","Non-Critical"))) -> Leverage
... A61: =Vendors!A61 -> V060 | B61: =INDEX(Vendors!$B$2:$B$61,MATCH(A61,Vendors!$A$2:$A$61,0)) -> Delta Supplies | C61: =INDEX(Vendors!$C$2:$C$61,MATCH(A61,Vendors!$A$2:$A$61,0)) -> Electronics | D61: =COUNTIF(PurchaseOrders!$B$2:$B$3001,A61) -> 45 | E61: =IFERROR(AVERAGEIFS(PurchaseOrders!$K$2:$K$3001,PurchaseOrders!$B$2:$B$3001,A61),0) -> 0.35555556 | F61: =IFERROR(AVERAGEIFS(PurchaseOrders!$J$2:$J$3001,PurchaseOrders!$B$2:$B$3001,A61),0) -> 1.0888889 | G61: =IFERROR(AVERAGEIFS(PurchaseOrders!$L$2:$L$3001,PurchaseOrders!$B$2:$B$3001,A61),0) -> 0.97427859 | H61: =IFERROR(AVERAGEIFS(PurchaseOrders!$M$2:$M$3001,PurchaseOrders!$B$2:$B$3001,A61),0) -> 0.015662664 | I61: =IFERROR(SUMIFS(QualityInspections!$D$2:$D$3001,QualityInspections!$G$2:$G$3001,A61)/SUMIFS(QualityInspections!$C$2:$C$3001,QualityInspections!$G$2:$G$3001,A61),0) -> 0.012947977 | J61: =1-E61 -> 0.64444444 | K61: =I61 -> 0.012947977 | L61: =MAX(H61,0) -> 0.015662664 | M61: =1-G61 -> 0.025721408 | N61: =IFERROR((J61-MIN($J$2:$J$61))/(MAX($J$2:$J$61)-MIN($J$2:$J$61))*100,0) -> 59.59596 | O61: =IFERROR((K61-MIN($K$2:$K$61))/(MAX($K$2:$K$61)-MIN($K$2:$K$61))*100,0) -> 2.0336743 | P61: =IFERROR((L61-MIN($L$2:$L$61))/(MAX($L$2:$L$61)-MIN($L$2:$L$61))*100,0) -> 13.842051 | Q61: =IFERROR((M61-MIN($M$2:$M$61))/(MAX($M$2:$M$61)-MIN($M$2:$M$61))*100,0) -> 15.28232 | R61: =0.35*N61+0.3*O61+0.2*P61+0.15*Q61 -> 26.529446 | S61: =IF(R61>=65,"High",IF(R61>=40,"Medium","Low")) -> Low | T61: =RANK(R61,$R$2:$R$61,0) -> 44 | U61: =SUMIFS(PurchaseOrders!$N$2:$N$3001,PurchaseOrders!$B$2:$B$3001,A61) -> 6364869.4 | V61: =IF(R61>=MEDIAN($R$2:$R$61),"High Risk","Low Risk") -> Low Risk | W61: =IF(U61>=MEDIAN($U$2:$U$61),"High Spend","Low Spend") -> High Spend | X61: =IF(AND(V61="High Risk",W61="High Spend"),"Strategic",IF(AND(V61="High Risk",W61="Low Spend"),"Bottleneck",IF(AND(V61="Low Risk",W61="High Spend"),"Leverage","Non-Critical"))) -> Leverage
A63: ASSUMPTIONS: RiskScore = 35% DelayRiskNorm + 30% DefectRiskNorm + 20% PriceRiskNorm + 15% FillRiskNorm (weights are a business judgment: delay & quality most directly cause production downtime). RiskTier thresholds: High >=65, Medium 40-64.9, Low <40 (analyst-set thresholds, adjustable). Normalization is min-max across this vendor set, i.e. relative ranking, not an absolute industry benchmark.
